Workbook

Sheet Briefcase cash and runway
A1: Briefcase cash and runway
A2: Briefcase — Runway & decisions · Briefcase Base
A4: Variable / dimension | B4: 2026-09 | C4: 2026-10 | D4: 2026-11 | E4: 2026-12 | F4: 2027-01 | G4: 2027-02 | H4: 2027-03 | I4: 2027-04 | J4: 2027-05 | K4: 2027-06 | L4: 2027-07 | M4: 2027-08 | N4: 2027-09 | O4: 2027-10 | P4: 2027-11 | Q4: 2027-12
A5: Cash balance | B5: ="" | C5: ="" | D5: ="" | E5: ="" | F5: ="" | G5: ="" | H5: ="" | I5: ="" | ... Q5: =""
A6: Bootstrapped — $0 | B6: =IF('Model inputs'!Z121="","",'Model inputs'!Z121) -> 0 | C6: ='Briefcase cash and runway'!B6+'Briefcase conversion and cost s'!B65 -> 1810 | D6: ='Briefcase cash and runway'!C6+'Model inputs'!L83 -> 3620 | E6: ='Briefcase cash and runway'!D6+'Model inputs'!M83 -> 5430 | F6: ='Briefcase cash and runway'!E6+'Model inputs'!N83 -> 7240 | G6: ='Briefcase cash and runway'!F6+'Model inputs'!O83 -> 9050 | H6: ='Briefcase cash and runway'!G6+'Model inputs'!P83 -> 10860 | I6: ='Briefcase cash and runway'!H6+'Model inputs'!Q83 -> 12670 | J6: ='Briefcase cash and runway'!I6+'Model inputs'!R83 -> 14480 | K6: ='Briefcase cash and runway'!J6+'Model inputs'!S83 -> 16290 | ... Q6: ='Briefcase cash and runway'!P6+'Model inputs'!Y83 -> 27150
A7: Illustrative pre-seed — $25,000 | B7: =IF('Model inputs'!Z122="","",'Model inputs'!Z122) -> 25000 | C7: ='Briefcase cash and runway'!B7+'Briefcase conversion and cost s'!B65 -> 26810 | D7: ='Briefcase cash and runway'!C7+'Model inputs'!L83 -> 28620 | E7: ='Briefcase cash and runway'!D7+'Model inputs'!M83 -> 30430 | F7: ='Briefcase cash and runway'!E7+'Model inputs'!N83 -> 32240 | G7: ='Briefcase cash and runway'!F7+'Model inputs'!O83 -> 34050 | H7: ='Briefcase cash and runway'!G7+'Model inputs'!P83 -> 35860 | I7: ='Briefcase cash and runway'!H7+'Model inputs'!Q83 -> 37670 | J7: ='Briefcase cash and runway'!I7+'Model inputs'!R83 -> 39480 | K7: ='Briefcase cash and runway'!J7+'Model inputs'!S83 -> 41290 | ... Q7: ='Briefcase cash and runway'!P7+'Model inputs'!Y83 -> 52150
A8: Lean launch — $5,000 | B8: =IF('Model inputs'!Z123="","",'Model inputs'!Z123) -> 5000 | C8: ='Briefcase cash and runway'!B8+'Briefcase conversion and cost s'!B65 -> 6810 | D8: ='Briefcase cash and runway'!C8+'Model inputs'!L83 -> 8620 | E8: ='Briefcase cash and runway'!D8+'Model inputs'!M83 -> 10430 | F8: ='Briefcase cash and runway'!E8+'Model inputs'!N83 -> 12240 | G8: ='Briefcase cash and runway'!F8+'Model inputs'!O83 -> 14050 | H8: ='Briefcase cash and runway'!G8+'Model inputs'!P83 -> 15860 | I8: ='Briefcase cash and runway'!H8+'Model inputs'!Q83 -> 17670 | J8: ='Briefcase cash and runway'!I8+'Model inputs'!R83 -> 19480 | K8: ='Briefcase cash and runway'!J8+'Model inputs'!S83 -> 21290 | ... Q8: ='Briefcase cash and runway'!P8+'Model inputs'!Y83 -> 32150
A9: Full-allowance cash balance | B9: ="" | C9: ="" | D9: ="" | E9: ="" | F9: ="" | G9: ="" | H9: ="" | I9: ="" | ... Q9: =""
A10: Bootstrapped — $0 | B10: =IF('Model inputs'!Z121="","",'Model inputs'!Z121) -> 0 | C10: ='Briefcase cash and runway'!B10+'Briefcase conversion and cost s'!B77 -> -2018 | D10: ='Briefcase cash and runway'!C10+'Model inputs'!L46 -> -4036 | E10: ='Briefcase cash and runway'!D10+'Model inputs'!M46 -> -6054 | F10: ='Briefcase cash and runway'!E10+'Model inputs'!N46 -> -8072 | G10: ='Briefcase cash and runway'!F10+'Model inputs'!O46 -> -10090 | H10: ='Briefcase cash and runway'!G10+'Model inputs'!P46 -> -12108 | I10: ='Briefcase cash and runway'!H10+'Model inputs'!Q46 -> -14126 | J10: ='Briefcase cash and runway'!I10+'Model inputs'!R46 -> -16144 | K10: ='Briefcase cash and runway'!J10+'Model inputs'!S46 -> -18162 | ... Q10: ='Briefcase cash and runway'!P10+'Model inputs'!Y46 -> -30270
A11: Illustrative pre-seed — $25,000 | B11: =IF('Model inputs'!Z122="","",'Model inputs'!Z122) -> 25000 | C11: ='Briefcase cash and runway'!B11+'Briefcase conversion and cost s'!B77 -> 22982 | D11: ='Briefcase cash and runway'!C11+'Model inputs'!L46 -> 20964 | E11: ='Briefcase cash and runway'!D11+'Model inputs'!M46 -> 18946 | F11: ='Briefcase cash and runway'!E11+'Model inputs'!N46 -> 16928 | G11: ='Briefcase cash and runway'!F11+'Model inputs'!O46 -> 14910 | H11: ='Briefcase cash and runway'!G11+'Model inputs'!P46 -> 12892 | I11: ='Briefcase cash and runway'!H11+'Model inputs'!Q46 -> 10874 | J11: ='Briefcase cash and runway'!I11+'Model inputs'!R46 -> 8856 | K11: ='Briefcase cash and runway'!J11+'Model inputs'!S46 -> 6838 | ... Q11: ='Briefcase cash and runway'!P11+'Model inputs'!Y46 -> -5270
A12: Lean launch — $5,000 | B12: =IF('Model inputs'!Z123="","",'Model inputs'!Z123) -> 5000 | C12: ='Briefcase cash and runway'!B12+'Briefcase conversion and cost s'!B77 -> 2982 | D12: ='Briefcase cash and runway'!C12+'Model inputs'!L46 -> 964 | E12: ='Briefcase cash and runway'!D12+'Model inputs'!M46 -> -1054 | F12: ='Briefcase cash and runway'!E12+'Model inputs'!N46 -> -3072 | G12: ='Briefcase cash and runway'!F12+'Model inputs'!O46 -> -5090 | H12: ='Briefcase cash and runway'!G12+'Model inputs'!P46 -> -7108 | I12: ='Briefcase cash and runway'!H12+'Model inputs'!Q46 -> -9126 | J12: ='Briefcase cash and runway'!I12+'Model inputs'!R46 -> -11144 | K12: ='Briefcase cash and runway'!J12+'Model inputs'!S46 -> -13162 | ... Q12: ='Briefcase cash and runway'!P12+'Model inputs'!Y46 -> -25270
A13: Runway from launch in months | B13: =SUM('Briefcase cash and runway'!B14,'Briefcase cash and runway'!B15,'Briefcase cash and runway'!B16) -> 0 | C13: ="" | D13: ="" | E13: ="" | F13: ="" | G13: ="" | H13: ="" | I13: ="" | J13: ="" | ... Q13: =""
A14: Bootstrapped — $0 | B14: =0 -> 0 | C14: =IF(IF(IF(ISERROR('Briefcase conversion and cost s'!B65<0),'Briefcase conversion and cost s'!B65<0,IF('Briefcase conversion and cost s'!B65="","",'Briefcase conversion and cost s'!B65<0))="",FALSE,IF(ISERROR('Briefcase conversion and cost s'!B65<0),'Briefcase conversion and cost s'!B65<0,IF('Briefcase conversion and cost s'!B65="","",'Briefcase conversion and cost s'!B65<0))),'Model inputs'!Z121/-'Briefcase conversion and cost s'!B65,"") | D14: =IF(IF(IF(ISERROR('Model inputs'!L83<0),'Model inputs'!L83<0,IF('Model inputs'!L83="","",'Model inputs'!L83<0))="",FALSE,IF(ISERROR('Model inputs'!L83<0),'Model inputs'!L83<0,IF('Model inputs'!L83="","",'Model inputs'!L83<0))),'Model inputs'!Z121/-'Model inputs'!L83,"") | E14: =IF(IF(IF(ISERROR('Model inputs'!M83<0),'Model inputs'!M83<0,IF('Model inputs'!M83="","",'Model inputs'!M83<0))="",FALSE,IF(ISERROR('Model inputs'!M83<0),'Model inputs'!M83<0,IF('Model inputs'!M83="","",'Model inputs'!M83<0))),'Model inputs'!Z121/-'Model inputs'!M83,"") | F14: =IF(IF(IF(ISERROR('Model inputs'!N83<0),'Model inputs'!N83<0,IF('Model inputs'!N83="","",'Model inputs'!N83<0))="",FALSE,IF(ISERROR('Model inputs'!N83<0),'Model inputs'!N83<0,IF('Model inputs'!N83="","",'Model inputs'!N83<0))),'Model inputs'!Z121/-'Model inputs'!N83,"") | G14: =IF(IF(IF(ISERROR('Model inputs'!O83<0),'Model inputs'!O83<0,IF('Model inputs'!O83="","",'Model inputs'!O83<0))="",FALSE,IF(ISERROR('Model inputs'!O83<0),'Model inputs'!O83<0,IF('Model inputs'!O83="","",'Model inputs'!O83<0))),'Model inputs'!Z121/-'Model inputs'!O83,"") | H14: =IF(IF(IF(ISERROR('Model inputs'!P83<0),'Model inputs'!P83<0,IF('Model inputs'!P83="","",'Model inputs'!P83<0))="",FALSE,IF(ISERROR('Model inputs'!P83<0),'Model inputs'!P83<0,IF('Model inputs'!P83="","",'Model inputs'!P83<0))),'Model inputs'!Z121/-'Model inputs'!P83,"") | I14: =IF(IF(IF(ISERROR('Model inputs'!Q83<0),'Model inputs'!Q83<0,IF('Model inputs'!Q83="","",'Model inputs'!Q83<0))="",FALSE,IF(ISERROR('Model inputs'!Q83<0),'Model inputs'!Q83<0,IF('Model inputs'!Q83="","",'Model inputs'!Q83<0))),'Model inputs'!Z121/-'Model inputs'!Q83,"") | J14: =IF(IF(IF(ISERROR('Model inputs'!R83<0),'Model inputs'!R83<0,IF('Model inputs'!R83="","",'Model inputs'!R83<0))="",FALSE,IF(ISERROR('Model inputs'!R83<0),'Model inputs'!R83<0,IF('Model inputs'!R83="","",'Model inputs'!R83<0))),'Model inputs'!Z121/-'Model inputs'!R83,"") | K14: =IF(IF(IF(ISERROR('Model inputs'!S83<0),'Model inputs'!S83<0,IF('Model inputs'!S83="","",'Model inputs'!S83<0))="",FALSE,IF(ISERROR('Model inputs'!S83<0),'Model inputs'!S83<0,IF('Model inputs'!S83="","",'Model inputs'!S83<0))),'Model inputs'!Z121/-'Model inputs'!S83,"") | L14: =IF(IF(IF(ISERROR('Model inputs'!T83<0),'Model inputs'!T83<0,IF('Model inputs'!T83="","",'Model inputs'!T83<0))="",FALSE,IF(ISERROR('Model inputs'!T83<0),'Model inputs'!T83<0,IF('Model inputs'!T83="","",'Model inputs'!T83<0))),'Model inputs'!Z121/-'Model inputs'!T83,"") | M14: =IF(IF(IF(ISERROR('Model inputs'!U83<0),'Model inputs'!U83<0,IF('Model inputs'!U83="","",'Model inputs'!U83<0))="",FALSE,IF(ISERROR('Model inputs'!U83<0),'Model inputs'!U83<0,IF('Model inputs'!U83="","",'Model inputs'!U83<0))),'Model inputs'!Z121/-'Model inputs'!U83,"") | N14: =IF(IF(IF(ISERROR('Model inputs'!V83<0),'Model inputs'!V83<0,IF('Model inputs'!V83="","",'Model inputs'!V83<0))="",FALSE,IF(ISERROR('Model inputs'!V83<0),'Model inputs'!V83<0,IF('Model inputs'!V83="","",'Model inputs'!V83<0))),'Model inputs'!Z121/-'Model inputs'!V83,"") | O14: =IF(IF(IF(ISERROR('Model inputs'!W83<0),'Model inputs'!W83<0,IF('Model inputs'!W83="","",'Model inputs'!W83<0))="",FALSE,IF(ISERROR('Model inputs'!W83<0),'Model inputs'!W83<0,IF('Model inputs'!W83="","",'Model inputs'!W83<0))),'Model inputs'!Z121/-'Model inputs'!W83,"") | P14: =IF(IF(IF(ISERROR('Model inputs'!X83<0),'Model inputs'!X83<0,IF('Model inputs'!X83="","",'Model inputs'!X83<0))="",FALSE,IF(ISERROR('Model inputs'!X83<0),'Model inputs'!X83<0,IF('Model inputs'!X83="","",'Model inputs'!X83<0))),'Model inputs'!Z121/-'Model inputs'!X83,"") | Q14: =IF(IF(IF(ISERROR('Model inputs'!Y83<0),'Model inputs'!Y83<0,IF('Model inputs'!Y83="","",'Model inputs'!Y83<0))="",FALSE,IF(ISERROR('Model inputs'!Y83<0),'Model inputs'!Y83<0,IF('Model inputs'!Y83="","",'Model inputs'!Y83<0))),'Model inputs'!Z121/-'Model inputs'!Y83,"")
A15: Illustrative pre-seed — $25,000 | B15: =0 -> 0 | C15: =IF(IF(IF(ISERROR('Briefcase conversion and cost s'!B65<0),'Briefcase conversion and cost s'!B65<0,IF('Briefcase conversion and cost s'!B65="","",'Briefcase conversion and cost s'!B65<0))="",FALSE,IF(ISERROR('Briefcase conversion and cost s'!B65<0),'Briefcase conversion and cost s'!B65<0,IF('Briefcase conversion and cost s'!B65="","",'Briefcase conversion and cost s'!B65<0))),'Model inputs'!Z122/-'Briefcase conversion and cost s'!B65,"") | D15: =IF(IF(IF(ISERROR('Model inputs'!L83<0),'Model inputs'!L83<0,IF('Model inputs'!L83="","",'Model inputs'!L83<0))="",FALSE,IF(ISERROR('Model inputs'!L83<0),'Model inputs'!L83<0,IF('Model inputs'!L83="","",'Model inputs'!L83<0))),'Model inputs'!Z122/-'Model inputs'!L83,"") | E15: =IF(IF(IF(ISERROR('Model inputs'!M83<0),'Model inputs'!M83<0,IF('Model inputs'!M83="","",'Model inputs'!M83<0))="",FALSE,IF(ISERROR('Model inputs'!M83<0),'Model inputs'!M83<0,IF('Model inputs'!M83="","",'Model inputs'!M83<0))),'Model inputs'!Z122/-'Model inputs'!M83,"") | F15: =IF(IF(IF(ISERROR('Model inputs'!N83<0),'Model inputs'!N83<0,IF('Model inputs'!N83="","",'Model inputs'!N83<0))="",FALSE,IF(ISERROR('Model inputs'!N83<0),'Model inputs'!N83<0,IF('Model inputs'!N83="","",'Model inputs'!N83<0))),'Model inputs'!Z122/-'Model inputs'!N83,"") | G15: =IF(IF(IF(ISERROR('Model inputs'!O83<0),'Model inputs'!O83<0,IF('Model inputs'!O83="","",'Model inputs'!O83<0))="",FALSE,IF(ISERROR('Model inputs'!O83<0),'Model inputs'!O83<0,IF('Model inputs'!O83="","",'Model inputs'!O83<0))),'Model inputs'!Z122/-'Model inputs'!O83,"") | H15: =IF(IF(IF(ISERROR('Model inputs'!P83<0),'Model inputs'!P83<0,IF('Model inputs'!P83="","",'Model inputs'!P83<0))="",FALSE,IF(ISERROR('Model inputs'!P83<0),'Model inputs'!P83<0,IF('Model inputs'!P83="","",'Model inputs'!P83<0))),'Model inputs'!Z122/-'Model inputs'!P83,"") | I15: =IF(IF(IF(ISERROR('Model inputs'!Q83<0),'Model inputs'!Q83<0,IF('Model inputs'!Q83="","",'Model inputs'!Q83<0))="",FALSE,IF(ISERROR('Model inputs'!Q83<0),'Model inputs'!Q83<0,IF('Model inputs'!Q83="","",'Model inputs'!Q83<0))),'Model inputs'!Z122/-'Model inputs'!Q83,"") | J15: =IF(IF(IF(ISERROR('Model inputs'!R83<0),'Model inputs'!R83<0,IF('Model inputs'!R83="","",'Model inputs'!R83<0))="",FALSE,IF(ISERROR('Model inputs'!R83<0),'Model inputs'!R83<0,IF('Model inputs'!R83="","",'Model inputs'!R83<0))),'Model inputs'!Z122/-'Model inputs'!R83,"") | K15: =IF(IF(IF(ISERROR('Model inputs'!S83<0),'Model inputs'!S83<0,IF('Model inputs'!S83="","",'Model inputs'!S83<0))="",FALSE,IF(ISERROR('Model inputs'!S83<0),'Model inputs'!S83<0,IF('Model inputs'!S83="","",'Model inputs'!S83<0))),'Model inputs'!Z122/-'Model inputs'!S83,"") | L15: =IF(IF(IF(ISERROR('Model inputs'!T83<0),'Model inputs'!T83<0,IF('Model inputs'!T83="","",'Model inputs'!T83<0))="",FALSE,IF(ISERROR('Model inputs'!T83<0),'Model inputs'!T83<0,IF('Model inputs'!T83="","",'Model inputs'!T83<0))),'Model inputs'!Z122/-'Model inputs'!T83,"") | M15: =IF(IF(IF(ISERROR('Model inputs'!U83<0),'Model inputs'!U83<0,IF('Model inputs'!U83="","",'Model inputs'!U83<0))="",FALSE,IF(ISERROR('Model inputs'!U83<0),'Model inputs'!U83<0,IF('Model inputs'!U83="","",'Model inputs'!U83<0))),'Model inputs'!Z122/-'Model inputs'!U83,"") | N15: =IF(IF(IF(ISERROR('Model inputs'!V83<0),'Model inputs'!V83<0,IF('Model inputs'!V83="","",'Model inputs'!V83<0))="",FALSE,IF(ISERROR('Model inputs'!V83<0),'Model inputs'!V83<0,IF('Model inputs'!V83="","",'Model inputs'!V83<0))),'Model inputs'!Z122/-'Model inputs'!V83,"") | O15: =IF(IF(IF(ISERROR('Model inputs'!W83<0),'Model inputs'!W83<0,IF('Model inputs'!W83="","",'Model inputs'!W83<0))="",FALSE,IF(ISERROR('Model inputs'!W83<0),'Model inputs'!W83<0,IF('Model inputs'!W83="","",'Model inputs'!W83<0))),'Model inputs'!Z122/-'Model inputs'!W83,"") | P15: =IF(IF(IF(ISERROR('Model inputs'!X83<0),'Model inputs'!X83<0,IF('Model inputs'!X83="","",'Model inputs'!X83<0))="",FALSE,IF(ISERROR('Model inputs'!X83<0),'Model inputs'!X83<0,IF('Model inputs'!X83="","",'Model inputs'!X83<0))),'Model inputs'!Z122/-'Model inputs'!X83,"") | Q15: =IF(IF(IF(ISERROR('Model inputs'!Y83<0),'Model inputs'!Y83<0,IF('Model inputs'!Y83="","",'Model inputs'!Y83<0))="",FALSE,IF(ISERROR('Model inputs'!Y83<0),'Model inputs'!Y83<0,IF('Model inputs'!Y83="","",'Model inputs'!Y83<0))),'Model inputs'!Z122/-'Model inputs'!Y83,"")
A16: Lean launch — $5,000 | B16: =0 -> 0 | C16: =IF(IF(IF(ISERROR('Briefcase conversion and cost s'!B65<0),'Briefcase conversion and cost s'!B65<0,IF('Briefcase conversion and cost s'!B65="","",'Briefcase conversion and cost s'!B65<0))="",FALSE,IF(ISERROR('Briefcase conversion and cost s'!B65<0),'Briefcase conversion and cost s'!B65<0,IF('Briefcase conversion and cost s'!B65="","",'Briefcase conversion and cost s'!B65<0))),'Model inputs'!Z123/-'Briefcase conversion and cost s'!B65,"") | D16: =IF(IF(IF(ISERROR('Model inputs'!L83<0),'Model inputs'!L83<0,IF('Model inputs'!L83="","",'Model inputs'!L83<0))="",FALSE,IF(ISERROR('Model inputs'!L83<0),'Model inputs'!L83<0,IF('Model inputs'!L83="","",'Model inputs'!L83<0))),'Model inputs'!Z123/-'Model inputs'!L83,"") | E16: =IF(IF(IF(ISERROR('Model inputs'!M83<0),'Model inputs'!M83<0,IF('Model inputs'!M83="","",'Model inputs'!M83<0))="",FALSE,IF(ISERROR('Model inputs'!M83<0),'Model inputs'!M83<0,IF('Model inputs'!M83="","",'Model inputs'!M83<0))),'Model inputs'!Z123/-'Model inputs'!M83,"") | F16: =IF(IF(IF(ISERROR('Model inputs'!N83<0),'Model inputs'!N83<0,IF('Model inputs'!N83="","",'Model inputs'!N83<0))="",FALSE,IF(ISERROR('Model inputs'!N83<0),'Model inputs'!N83<0,IF('Model inputs'!N83="","",'Model inputs'!N83<0))),'Model inputs'!Z123/-'Model inputs'!N83,"") | G16: =IF(IF(IF(ISERROR('Model inputs'!O83<0),'Model inputs'!O83<0,IF('Model inputs'!O83="","",'Model inputs'!O83<0))="",FALSE,IF(ISERROR('Model inputs'!O83<0),'Model inputs'!O83<0,IF('Model inputs'!O83="","",'Model inputs'!O83<0))),'Model inputs'!Z123/-'Model inputs'!O83,"") | H16: =IF(IF(IF(ISERROR('Model inputs'!P83<0),'Model inputs'!P83<0,IF('Model inputs'!P83="","",'Model inputs'!P83<0))="",FALSE,IF(ISERROR('Model inputs'!P83<0),'Model inputs'!P83<0,IF('Model inputs'!P83="","",'Model inputs'!P83<0))),'Model inputs'!Z123/-'Model inputs'!P83,"") | I16: =IF(IF(IF(ISERROR('Model inputs'!Q83<0),'Model inputs'!Q83<0,IF('Model inputs'!Q83="","",'Model inputs'!Q83<0))="",FALSE,IF(ISERROR('Model inputs'!Q83<0),'Model inputs'!Q83<0,IF('Model inputs'!Q83="","",'Model inputs'!Q83<0))),'Model inputs'!Z123/-'Model inputs'!Q83,"") | J16: =IF(IF(IF(ISERROR('Model inputs'!R83<0),'Model inputs'!R83<0,IF('Model inputs'!R83="","",'Model inputs'!R83<0))="",FALSE,IF(ISERROR('Model inputs'!R83<0),'Model inputs'!R83<0,IF('Model inputs'!R83="","",'Model inputs'!R83<0))),'Model inputs'!Z123/-'Model inputs'!R83,"") | K16: =IF(IF(IF(ISERROR('Model inputs'!S83<0),'Model inputs'!S83<0,IF('Model inputs'!S83="","",'Model inputs'!S83<0))="",FALSE,IF(ISERROR('Model inputs'!S83<0),'Model inputs'!S83<0,IF('Model inputs'!S83="","",'Model inputs'!S83<0))),'Model inputs'!Z123/-'Model inputs'!S83,"") | L16: =IF(IF(IF(ISERROR('Model inputs'!T83<0),'Model inputs'!T83<0,IF('Model inputs'!T83="","",'Model inputs'!T83<0))="",FALSE,IF(ISERROR('Model inputs'!T83<0),'Model inputs'!T83<0,IF('Model inputs'!T83="","",'Model inputs'!T83<0))),'Model inputs'!Z123/-'Model inputs'!T83,"") | M16: =IF(IF(IF(ISERROR('Model inputs'!U83<0),'Model inputs'!U83<0,IF('Model inputs'!U83="","",'Model inputs'!U83<0))="",FALSE,IF(ISERROR('Model inputs'!U83<0),'Model inputs'!U83<0,IF('Model inputs'!U83="","",'Model inputs'!U83<0))),'Model inputs'!Z123/-'Model inputs'!U83,"") | N16: =IF(IF(IF(ISERROR('Model inputs'!V83<0),'Model inputs'!V83<0,IF('Model inputs'!V83="","",'Model inputs'!V83<0))="",FALSE,IF(ISERROR('Model inputs'!V83<0),'Model inputs'!V83<0,IF('Model inputs'!V83="","",'Model inputs'!V83<0))),'Model inputs'!Z123/-'Model inputs'!V83,"") | O16: =IF(IF(IF(ISERROR('Model inputs'!W83<0),'Model inputs'!W83<0,IF('Model inputs'!W83="","",'Model inputs'!W83<0))="",FALSE,IF(ISERROR('Model inputs'!W83<0),'Model inputs'!W83<0,IF('Model inputs'!W83="","",'Model inputs'!W83<0))),'Model inputs'!Z123/-'Model inputs'!W83,"") | P16: =IF(IF(IF(ISERROR('Model inputs'!X83<0),'Model inputs'!X83<0,IF('Model inputs'!X83="","",'Model inputs'!X83<0))="",FALSE,IF(ISERROR('Model inputs'!X83<0),'Model inputs'!X83<0,IF('Model inputs'!X83="","",'Model inputs'!X83<0))),'Model inputs'!Z123/-'Model inputs'!X83,"") | Q16: =IF(IF(IF(ISERROR('Model inputs'!Y83<0),'Model inputs'!Y83<0,IF('Model inputs'!Y83="","",'Model inputs'!Y83<0))="",FALSE,IF(ISERROR('Model inputs'!Y83<0),'Model inputs'!Y83<0,IF('Model inputs'!Y83="","",'Model inputs'!Y83<0))),'Model inputs'!Z123/-'Model inputs'!Y83,"")
A17: Full-allowance runway in months | B17: =SUM('Briefcase cash and runway'!B18,'Briefcase cash and runway'!B19,'Briefcase cash and runway'!B20) -> 0 | C17: ="" | D17: ="" | E17: ="" | F17: ="" | G17: ="" | H17: ="" | I17: ="" | J17: ="" | ... Q17: =""
A18: Bootstrapped — $0 | B18: =0 -> 0 | C18: =IF(IF(IF(ISERROR('Briefcase conversion and cost s'!B77<0),'Briefcase conversion and cost s'!B77<0,IF('Briefcase conversion and cost s'!B77="","",'Briefcase conversion and cost s'!B77<0))="",FALSE,IF(ISERROR('Briefcase conversion and cost s'!B77<0),'Briefcase conversion and cost s'!B77<0,IF('Briefcase conversion and cost s'!B77="","",'Briefcase conversion and cost s'!B77<0))),'Model inputs'!Z121/-'Briefcase conversion and cost s'!B77,"") -> 0 | D18: =IF(IF(IF(ISERROR('Model inputs'!L46<0),'Model inputs'!L46<0,IF('Model inputs'!L46="","",'Model inputs'!L46<0))="",FALSE,IF(ISERROR('Model inputs'!L46<0),'Model inputs'!L46<0,IF('Model inputs'!L46="","",'Model inputs'!L46<0))),'Model inputs'!Z121/-'Model inputs'!L46,"") -> 0 | E18: =IF(IF(IF(ISERROR('Model inputs'!M46<0),'Model inputs'!M46<0,IF('Model inputs'!M46="","",'Model inputs'!M46<0))="",FALSE,IF(ISERROR('Model inputs'!M46<0),'Model inputs'!M46<0,IF('Model inputs'!M46="","",'Model inputs'!M46<0))),'Model inputs'!Z121/-'Model inputs'!M46,"") -> 0 | F18: =IF(IF(IF(ISERROR('Model inputs'!N46<0),'Model inputs'!N46<0,IF('Model inputs'!N46="","",'Model inputs'!N46<0))="",FALSE,IF(ISERROR('Model inputs'!N46<0),'Model inputs'!N46<0,IF('Model inputs'!N46="","",'Model inputs'!N46<0))),'Model inputs'!Z121/-'Model inputs'!N46,"") -> 0 | G18: =IF(IF(IF(ISERROR('Model inputs'!O46<0),'Model inputs'!O46<0,IF('Model inputs'!O46="","",'Model inputs'!O46<0))="",FALSE,IF(ISERROR('Model inputs'!O46<0),'Model inputs'!O46<0,IF('Model inputs'!O46="","",'Model inputs'!O46<0))),'Model inputs'!Z121/-'Model inputs'!O46,"") -> 0 | H18: =IF(IF(IF(ISERROR('Model inputs'!P46<0),'Model inputs'!P46<0,IF('Model inputs'!P46="","",'Model inputs'!P46<0))="",FALSE,IF(ISERROR('Model inputs'!P46<0),'Model inputs'!P46<0,IF('Model inputs'!P46="","",'Model inputs'!P46<0))),'Model inputs'!Z121/-'Model inputs'!P46,"") -> 0 | I18: =IF(IF(IF(ISERROR('Model inputs'!Q46<0),'Model inputs'!Q46<0,IF('Model inputs'!Q46="","",'Model inputs'!Q46<0))="",FALSE,IF(ISERROR('Model inputs'!Q46<0),'Model inputs'!Q46<0,IF('Model inputs'!Q46="","",'Model inputs'!Q46<0))),'Model inputs'!Z121/-'Model inputs'!Q46,"") -> 0 | J18: =IF(IF(IF(ISERROR('Model inputs'!R46<0),'Model inputs'!R46<0,IF('Model inputs'!R46="","",'Model inputs'!R46<0))="",FALSE,IF(ISERROR('Model inputs'!R46<0),'Model inputs'!R46<0,IF('Model inputs'!R46="","",'Model inputs'!R46<0))),'Model inputs'!Z121/-'Model inputs'!R46,"") -> 0 | K18: =IF(IF(IF(ISERROR('Model inputs'!S46<0),'Model inputs'!S46<0,IF('Model inputs'!S46="","",'Model inputs'!S46<0))="",FALSE,IF(ISERROR('Model inputs'!S46<0),'Model inputs'!S46<0,IF('Model inputs'!S46="","",'Model inputs'!S46<0))),'Model inputs'!Z121/-'Model inputs'!S46,"") -> 0 | L18: =IF(IF(IF(ISERROR('Model inputs'!T46<0),'Model inputs'!T46<0,IF('Model inputs'!T46="","",'Model inputs'!T46<0))="",FALSE,IF(ISERROR('Model inputs'!T46<0),'Model inputs'!T46<0,IF('Model inputs'!T46="","",'Model inputs'!T46<0))),'Model inputs'!Z121/-'Model inputs'!T46,"") -> 0 | M18: =IF(IF(IF(ISERROR('Model inputs'!U46<0),'Model inputs'!U46<0,IF('Model inputs'!U46="","",'Model inputs'!U46<0))="",FALSE,IF(ISERROR('Model inputs'!U46<0),'Model inputs'!U46<0,IF('Model inputs'!U46="","",'Model inputs'!U46<0))),'Model inputs'!Z121/-'Model inputs'!U46,"") -> 0 | N18: =IF(IF(IF(ISERROR('Model inputs'!V46<0),'Model inputs'!V46<0,IF('Model inputs'!V46="","",'Model inputs'!V46<0))="",FALSE,IF(ISERROR('Model inputs'!V46<0),'Model inputs'!V46<0,IF('Model inputs'!V46="","",'Model inputs'!V46<0))),'Model inputs'!Z121/-'Model inputs'!V46,"") -> 0 | O18: =IF(IF(IF(ISERROR('Model inputs'!W46<0),'Model inputs'!W46<0,IF('Model inputs'!W46="","",'Model inputs'!W46<0))="",FALSE,IF(ISERROR('Model inputs'!W46<0),'Model inputs'!W46<0,IF('Model inputs'!W46="","",'Model inputs'!W46<0))),'Model inputs'!Z121/-'Model inputs'!W46,"") -> 0 | P18: =IF(IF(IF(ISERROR('Model inputs'!X46<0),'Model inputs'!X46<0,IF('Model inputs'!X46="","",'Model inputs'!X46<0))="",FALSE,IF(ISERROR('Model inputs'!X46<0),'Model inputs'!X46<0,IF('Model inputs'!X46="","",'Model inputs'!X46<0))),'Model inputs'!Z121/-'Model inputs'!X46,"") -> 0 | Q18: =IF(IF(IF(ISERROR('Model inputs'!Y46<0),'Model inputs'!Y46<0,IF('Model inputs'!Y46="","",'Model inputs'!Y46<0))="",FALSE,IF(ISERROR('Model inputs'!Y46<0),'Model inputs'!Y46<0,IF('Model inputs'!Y46="","",'Model inputs'!Y46<0))),'Model inputs'!Z121/-'Model inputs'!Y46,"") -> 0
A19: Illustrative pre-seed — $25,000 | B19: =0 -> 0 | C19: =IF(IF(IF(ISERROR('Briefcase conversion and cost s'!B77<0),'Briefcase conversion and cost s'!B77<0,IF('Briefcase conversion and cost s'!B77="","",'Briefcase conversion and cost s'!B77<0))="",FALSE,IF(ISERROR('Briefcase conversion and cost s'!B77<0),'Briefcase conversion and cost s'!B77<0,IF('Briefcase conversion and cost s'!B77="","",'Briefcase conversion and cost s'!B77<0))),'Model inputs'!Z122/-'Briefcase conversion and cost s'!B77,"") -> 12.388503 | D19: =IF(IF(IF(ISERROR('Model inputs'!L46<0),'Model inputs'!L46<0,IF('Model inputs'!L46="","",'Model inputs'!L46<0))="",FALSE,IF(ISERROR('Model inputs'!L46<0),'Model inputs'!L46<0,IF('Model inputs'!L46="","",'Model inputs'!L46<0))),'Model inputs'!Z122/-'Model inputs'!L46,"") -> 12.388503 | E19: =IF(IF(IF(ISERROR('Model inputs'!M46<0),'Model inputs'!M46<0,IF('Model inputs'!M46="","",'Model inputs'!M46<0))="",FALSE,IF(ISERROR('Model inputs'!M46<0),'Model inputs'!M46<0,IF('Model inputs'!M46="","",'Model inputs'!M46<0))),'Model inputs'!Z122/-'Model inputs'!M46,"") -> 12.388503 | F19: =IF(IF(IF(ISERROR('Model inputs'!N46<0),'Model inputs'!N46<0,IF('Model inputs'!N46="","",'Model inputs'!N46<0))="",FALSE,IF(ISERROR('Model inputs'!N46<0),'Model inputs'!N46<0,IF('Model inputs'!N46="","",'Model inputs'!N46<0))),'Model inputs'!Z122/-'Model inputs'!N46,"") -> 12.388503 | G19: =IF(IF(IF(ISERROR('Model inputs'!O46<0),'Model inputs'!O46<0,IF('Model inputs'!O46="","",'Model inputs'!O46<0))="",FALSE,IF(ISERROR('Model inputs'!O46<0),'Model inputs'!O46<0,IF('Model inputs'!O46="","",'Model inputs'!O46<0))),'Model inputs'!Z122/-'Model inputs'!O46,"") -> 12.388503 | H19: =IF(IF(IF(ISERROR('Model inputs'!P46<0),'Model inputs'!P46<0,IF('Model inputs'!P46="","",'Model inputs'!P46<0))="",FALSE,IF(ISERROR('Model inputs'!P46<0),'Model inputs'!P46<0,IF('Model inputs'!P46="","",'Model inputs'!P46<0))),'Model inputs'!Z122/-'Model inputs'!P46,"") -> 12.388503 | I19: =IF(IF(IF(ISERROR('Model inputs'!Q46<0),'Model inputs'!Q46<0,IF('Model inputs'!Q46="","",'Model inputs'!Q46<0))="",FALSE,IF(ISERROR('Model inputs'!Q46<0),'Model inputs'!Q46<0,IF('Model inputs'!Q46="","",'Model inputs'!Q46<0))),'Model inputs'!Z122/-'Model inputs'!Q46,"") -> 12.388503 | J19: =IF(IF(IF(ISERROR('Model inputs'!R46<0),'Model inputs'!R46<0,IF('Model inputs'!R46="","",'Model inputs'!R46<0))="",FALSE,IF(ISERROR('Model inputs'!R46<0),'Model inputs'!R46<0,IF('Model inputs'!R46="","",'Model inputs'!R46<0))),'Model inputs'!Z122/-'Model inputs'!R46,"") -> 12.388503 | K19: =IF(IF(IF(ISERROR('Model inputs'!S46<0),'Model inputs'!S46<0,IF('Model inputs'!S46="","",'Model inputs'!S46<0))="",FALSE,IF(ISERROR('Model inputs'!S46<0),'Model inputs'!S46<0,IF('Model inputs'!S46="","",'Model inputs'!S46<0))),'Model inputs'!Z122/-'Model inputs'!S46,"") -> 12.388503 | L19: =IF(IF(IF(ISERROR('Model inputs'!T46<0),'Model inputs'!T46<0,IF('Model inputs'!T46="","",'Model inputs'!T46<0))="",FALSE,IF(ISERROR('Model inputs'!T46<0),'Model inputs'!T46<0,IF('Model inputs'!T46="","",'Model inputs'!T46<0))),'Model inputs'!Z122/-'Model inputs'!T46,"") -> 12.388503 | M19: =IF(IF(IF(ISERROR('Model inputs'!U46<0),'Model inputs'!U46<0,IF('Model inputs'!U46="","",'Model inputs'!U46<0))="",FALSE,IF(ISERROR('Model inputs'!U46<0),'Model inputs'!U46<0,IF('Model inputs'!U46="","",'Model inputs'!U46<0))),'Model inputs'!Z122/-'Model inputs'!U46,"") -> 12.388503 | N19: =IF(IF(IF(ISERROR('Model inputs'!V46<0),'Model inputs'!V46<0,IF('Model inputs'!V46="","",'Model inputs'!V46<0))="",FALSE,IF(ISERROR('Model inputs'!V46<0),'Model inputs'!V46<0,IF('Model inputs'!V46="","",'Model inputs'!V46<0))),'Model inputs'!Z122/-'Model inputs'!V46,"") -> 12.388503 | O19: =IF(IF(IF(ISERROR('Model inputs'!W46<0),'Model inputs'!W46<0,IF('Model inputs'!W46="","",'Model inputs'!W46<0))="",FALSE,IF(ISERROR('Model inputs'!W46<0),'Model inputs'!W46<0,IF('Model inputs'!W46="","",'Model inputs'!W46<0))),'Model inputs'!Z122/-'Model inputs'!W46,"") -> 12.388503 | P19: =IF(IF(IF(ISERROR('Model inputs'!X46<0),'Model inputs'!X46<0,IF('Model inputs'!X46="","",'Model inputs'!X46<0))="",FALSE,IF(ISERROR('Model inputs'!X46<0),'Model inputs'!X46<0,IF('Model inputs'!X46="","",'Model inputs'!X46<0))),'Model inputs'!Z122/-'Model inputs'!X46,"") -> 12.388503 | Q19: =IF(IF(IF(ISERROR('Model inputs'!Y46<0),'Model inputs'!Y46<0,IF('Model inputs'!Y46="","",'Model inputs'!Y46<0))="",FALSE,IF(ISERROR('Model inputs'!Y46<0),'Model inputs'!Y46<0,IF('Model inputs'!Y46="","",'Model inputs'!Y46<0))),'Model inputs'!Z122/-'Model inputs'!Y46,"") -> 12.388503
A20: Lean launch — $5,000 | B20: =0 -> 0 | C20: =IF(IF(IF(ISERROR('Briefcase conversion and cost s'!B77<0),'Briefcase conversion and cost s'!B77<0,IF('Briefcase conversion and cost s'!B77="","",'Briefcase conversion and cost s'!B77<0))="",FALSE,IF(ISERROR('Briefcase conversion and cost s'!B77<0),'Briefcase conversion and cost s'!B77<0,IF('Briefcase conversion and cost s'!B77="","",'Briefcase conversion and cost s'!B77<0))),'Model inputs'!Z123/-'Briefcase conversion and cost s'!B77,"") -> 2.4777007 | D20: =IF(IF(IF(ISERROR('Model inputs'!L46<0),'Model inputs'!L46<0,IF('Model inputs'!L46="","",'Model inputs'!L46<0))="",FALSE,IF(ISERROR('Model inputs'!L46<0),'Model inputs'!L46<0,IF('Model inputs'!L46="","",'Model inputs'!L46<0))),'Model inputs'!Z123/-'Model inputs'!L46,"") -> 2.4777007 | E20: =IF(IF(IF(ISERROR('Model inputs'!M46<0),'Model inputs'!M46<0,IF('Model inputs'!M46="","",'Model inputs'!M46<0))="",FALSE,IF(ISERROR('Model inputs'!M46<0),'Model inputs'!M46<0,IF('Model inputs'!M46="","",'Model inputs'!M46<0))),'Model inputs'!Z123/-'Model inputs'!M46,"") -> 2.4777007 | F20: =IF(IF(IF(ISERROR('Model inputs'!N46<0),'Model inputs'!N46<0,IF('Model inputs'!N46="","",'Model inputs'!N46<0))="",FALSE,IF(ISERROR('Model inputs'!N46<0),'Model inputs'!N46<0,IF('Model inputs'!N46="","",'Model inputs'!N46<0))),'Model inputs'!Z123/-'Model inputs'!N46,"") -> 2.4777007 | G20: =IF(IF(IF(ISERROR('Model inputs'!O46<0),'Model inputs'!O46<0,IF('Model inputs'!O46="","",'Model inputs'!O46<0))="",FALSE,IF(ISERROR('Model inputs'!O46<0),'Model inputs'!O46<0,IF('Model inputs'!O46="","",'Model inputs'!O46<0))),'Model inputs'!Z123/-'Model inputs'!O46,"") -> 2.4777007 | H20: =IF(IF(IF(ISERROR('Model inputs'!P46<0),'Model inputs'!P46<0,IF('Model inputs'!P46="","",'Model inputs'!P46<0))="",FALSE,IF(ISERROR('Model inputs'!P46<0),'Model inputs'!P46<0,IF('Model inputs'!P46="","",'Model inputs'!P46<0))),'Model inputs'!Z123/-'Model inputs'!P46,"") -> 2.4777007 | I20: =IF(IF(IF(ISERROR('Model inputs'!Q46<0),'Model inputs'!Q46<0,IF('Model inputs'!Q46="","",'Model inputs'!Q46<0))="",FALSE,IF(ISERROR('Model inputs'!Q46<0),'Model inputs'!Q46<0,IF('Model inputs'!Q46="","",'Model inputs'!Q46<0))),'Model inputs'!Z123/-'Model inputs'!Q46,"") -> 2.4777007 | J20: =IF(IF(IF(ISERROR('Model inputs'!R46<0),'Model inputs'!R46<0,IF('Model inputs'!R46="","",'Model inputs'!R46<0))="",FALSE,IF(ISERROR('Model inputs'!R46<0),'Model inputs'!R46<0,IF('Model inputs'!R46="","",'Model inputs'!R46<0))),'Model inputs'!Z123/-'Model inputs'!R46,"") -> 2.4777007 | K20: =IF(IF(IF(ISERROR('Model inputs'!S46<0),'Model inputs'!S46<0,IF('Model inputs'!S46="","",'Model inputs'!S46<0))="",FALSE,IF(ISERROR('Model inputs'!S46<0),'Model inputs'!S46<0,IF('Model inputs'!S46="","",'Model inputs'!S46<0))),'Model inputs'!Z123/-'Model inputs'!S46,"") -> 2.4777007 | L20: =IF(IF(IF(ISERROR('Model inputs'!T46<0),'Model inputs'!T46<0,IF('Model inputs'!T46="","",'Model inputs'!T46<0))="",FALSE,IF(ISERROR('Model inputs'!T46<0),'Model inputs'!T46<0,IF('Model inputs'!T46="","",'Model inputs'!T46<0))),'Model inputs'!Z123/-'Model inputs'!T46,"") -> 2.4777007 | M20: =IF(IF(IF(ISERROR('Model inputs'!U46<0),'Model inputs'!U46<0,IF('Model inputs'!U46="","",'Model inputs'!U46<0))="",FALSE,IF(ISERROR('Model inputs'!U46<0),'Model inputs'!U46<0,IF('Model inputs'!U46="","",'Model inputs'!U46<0))),'Model inputs'!Z123/-'Model inputs'!U46,"") -> 2.4777007 | N20: =IF(IF(IF(ISERROR('Model inputs'!V46<0),'Model inputs'!V46<0,IF('Model inputs'!V46="","",'Model inputs'!V46<0))="",FALSE,IF(ISERROR('Model inputs'!V46<0),'Model inputs'!V46<0,IF('Model inputs'!V46="","",'Model inputs'!V46<0))),'Model inputs'!Z123/-'Model inputs'!V46,"") -> 2.4777007 | O20: =IF(IF(IF(ISERROR('Model inputs'!W46<0),'Model inputs'!W46<0,IF('Model inputs'!W46="","",'Model inputs'!W46<0))="",FALSE,IF(ISERROR('Model inputs'!W46<0),'Model inputs'!W46<0,IF('Model inputs'!W46="","",'Model inputs'!W46<0))),'Model inputs'!Z123/-'Model inputs'!W46,"") -> 2.4777007 | P20: =IF(IF(IF(ISERROR('Model inputs'!X46<0),'Model inputs'!X46<0,IF('Model inputs'!X46="","",'Model inputs'!X46<0))="",FALSE,IF(ISERROR('Model inputs'!X46<0),'Model inputs'!X46<0,IF('Model inputs'!X46="","",'Model inputs'!X46<0))),'Model inputs'!Z123/-'Model inputs'!X46,"") -> 2.4777007 | Q20: =IF(IF(IF(ISERROR('Model inputs'!Y46<0),'Model inputs'!Y46<0,IF('Model inputs'!Y46="","",'Model inputs'!Y46<0))="",FALSE,IF(ISERROR('Model inputs'!Y46<0),'Model inputs'!Y46<0,IF('Model inputs'!Y46="","",'Model inputs'!Y46<0))),'Model inputs'!Z123/-'Model inputs'!Y46,"") -> 2.4777007
A21: Monthly burn | B21: 0 | C21: =MAX(0,-'Briefcase conversion and cost s'!B65) -> 0 | D21: =MAX(0,-'Model inputs'!L83) -> 0 | E21: =MAX(0,-'Model inputs'!M83) -> 0 | F21: =MAX(0,-'Model inputs'!N83) -> 0 | G21: =MAX(0,-'Model inputs'!O83) -> 0 | H21: =MAX(0,-'Model inputs'!P83) -> 0 | I21: =MAX(0,-'Model inputs'!Q83) -> 0 | J21: =MAX(0,-'Model inputs'!R83) -> 0 | K21: =MAX(0,-'Model inputs'!S83) -> 0 | ... Q21: =MAX(0,-'Model inputs'!Y83) -> 0
A22: Cash outlook | C22: ="" | D22: ="" | E22: ="" | F22: ="" | G22: ="" | H22: ="" | I22: ="" | J22: ="" | ... Q22: =""
A23: Bootstrapped — $0 | C23: =IF(IF(IF(ISERROR('Briefcase conversion and cost s'!B65>=0),'Briefcase conversion and cost s'!B65>=0,IF('Briefcase conversion and cost s'!B65="","",'Briefcase conversion and cost s'!B65>=0))="",FALSE,IF(ISERROR('Briefcase conversion and cost s'!B65>=0),'Briefcase conversion and cost s'!B65>=0,IF('Briefcase conversion and cost s'!B65="","",'Briefcase conversion and cost s'!B65>=0))),IF(IF(IF(ISERROR('Model inputs'!Z121=0),'Model inputs'!Z121=0,IF('Model inputs'!Z121="","",'Model inputs'!Z121=0))="",FALSE,IF(ISERROR('Model inputs'!Z121=0),'Model inputs'!Z121=0,IF('Model inputs'!Z121="","",'Model inputs'!Z121=0))),"Cash-positive; no launch buffer","Cash-positive within flat forecast"),"Cash-burning; see runway") -> Cash-positive; no launch buffer | D23: =IF(IF(IF(ISERROR('Model inputs'!L83>=0),'Model inputs'!L83>=0,IF('Model inputs'!L83="","",'Model inputs'!L83>=0))="",FALSE,IF(ISERROR('Model inputs'!L83>=0),'Model inputs'!L83>=0,IF('Model inputs'!L83="","",'Model inputs'!L83>=0))),IF(IF(IF(ISERROR('Model inputs'!Z121=0),'Model inputs'!Z121=0,IF('Model inputs'!Z121="","",'Model inputs'!Z121=0))="",FALSE,IF(ISERROR('Model inputs'!Z121=0),'Model inputs'!Z121=0,IF('Model inputs'!Z121="","",'Model inputs'!Z121=0))),"Cash-positive; no launch buffer","Cash-positive within flat forecast"),"Cash-burning; see runway") -> Cash-positive; no launch buffer | E23: =IF(IF(IF(ISERROR('Model inputs'!M83>=0),'Model inputs'!M83>=0,IF('Model inputs'!M83="","",'Model inputs'!M83>=0))="",FALSE,IF(ISERROR('Model inputs'!M83>=0),'Model inputs'!M83>=0,IF('Model inputs'!M83="","",'Model inputs'!M83>=0))),IF(IF(IF(ISERROR('Model inputs'!Z121=0),'Model inputs'!Z121=0,IF('Model inputs'!Z121="","",'Model inputs'!Z121=0))="",FALSE,IF(ISERROR('Model inputs'!Z121=0),'Model inputs'!Z121=0,IF('Model inputs'!Z121="","",'Model inputs'!Z121=0))),"Cash-positive; no launch buffer","Cash-positive within flat forecast"),"Cash-burning; see runway") -> Cash-positive; no launch buffer | F23: =IF(IF(IF(ISERROR('Model inputs'!N83>=0),'Model inputs'!N83>=0,IF('Model inputs'!N83="","",'Model inputs'!N83>=0))="",FALSE,IF(ISERROR('Model inputs'!N83>=0),'Model inputs'!N83>=0,IF('Model inputs'!N83="","",'Model inputs'!N83>=0))),IF(IF(IF(ISERROR('Model inputs'!Z121=0),'Model inputs'!Z121=0,IF('Model inputs'!Z121="","",'Model inputs'!Z121=0))="",FALSE,IF(ISERROR('Model inputs'!Z121=0),'Model inputs'!Z121=0,IF('Model inputs'!Z121="","",'Model inputs'!Z121=0))),"Cash-positive; no launch buffer","Cash-positive within flat forecast"),"Cash-burning; see runway") -> Cash-positive; no launch buffer | G23: =IF(IF(IF(ISERROR('Model inputs'!O83>=0),'Model inputs'!O83>=0,IF('Model inputs'!O83="","",'Model inputs'!O83>=0))="",FALSE,IF(ISERROR('Model inputs'!O83>=0),'Model inputs'!O83>=0,IF('Model inputs'!O83="","",'Model inputs'!O83>=0))),IF(IF(IF(ISERROR('Model inputs'!Z121=0),'Model inputs'!Z121=0,IF('Model inputs'!Z121="","",'Model inputs'!Z121=0))="",FALSE,IF(ISERROR('Model inputs'!Z121=0),'Model inputs'!Z121=0,IF('Model inputs'!Z121="","",'Model inputs'!Z121=0))),"Cash-positive; no launch buffer","Cash-positive within flat forecast"),"Cash-burning; see runway") -> Cash-positive; no launch buffer | H23: =IF(IF(IF(ISERROR('Model inputs'!P83>=0),'Model inputs'!P83>=0,IF('Model inputs'!P83="","",'Model inputs'!P83>=0))="",FALSE,IF(ISERROR('Model inputs'!P83>=0),'Model inputs'!P83>=0,IF('Model inputs'!P83="","",'Model inputs'!P83>=0))),IF(IF(IF(ISERROR('Model inputs'!Z121=0),'Model inputs'!Z121=0,IF('Model inputs'!Z121="","",'Model inputs'!Z121=0))="",FALSE,IF(ISERROR('Model inputs'!Z121=0),'Model inputs'!Z121=0,IF('Model inputs'!Z121="","",'Model inputs'!Z121=0))),"Cash-positive; no launch buffer","Cash-positive within flat forecast"),"Cash-burning; see runway") -> Cash-positive; no launch buffer | I23: =IF(IF(IF(ISERROR('Model inputs'!Q83>=0),'Model inputs'!Q83>=0,IF('Model inputs'!Q83="","",'Model inputs'!Q83>=0))="",FALSE,IF(ISERROR('Model inputs'!Q83>=0),'Model inputs'!Q83>=0,IF('Model inputs'!Q83="","",'Model inputs'!Q83>=0))),IF(IF(IF(ISERROR('Model inputs'!Z121=0),'Model inputs'!Z121=0,IF('Model inputs'!Z121="","",'Model inputs'!Z121=0))="",FALSE,IF(ISERROR('Model inputs'!Z121=0),'Model inputs'!Z121=0,IF('Model inputs'!Z121="","",'Model inputs'!Z121=0))),"Cash-positive; no launch buffer","Cash-positive within flat forecast"),"Cash-burning; see runway") -> Cash-positive; no launch buffer | J23: =IF(IF(IF(ISERROR('Model inputs'!R83>=0),'Model inputs'!R83>=0,IF('Model inputs'!R83="","",'Model inputs'!R83>=0))="",FALSE,IF(ISERROR('Model inputs'!R83>=0),'Model inputs'!R83>=0,IF('Model inputs'!R83="","",'Model inputs'!R83>=0))),IF(IF(IF(ISERROR('Model inputs'!Z121=0),'Model inputs'!Z121=0,IF('Model inputs'!Z121="","",'Model inputs'!Z121=0))="",FALSE,IF(ISERROR('Model inputs'!Z121=0),'Model inputs'!Z121=0,IF('Model inputs'!Z121="","",'Model inputs'!Z121=0))),"Cash-positive; no launch buffer","Cash-positive within flat forecast"),"Cash-burning; see runway") -> Cash-positive; no launch buffer | K23: =IF(IF(IF(ISERROR('Model inputs'!S83>=0),'Model inputs'!S83>=0,IF('Model inputs'!S83="","",'Model inputs'!S83>=0))="",FALSE,IF(ISERROR('Model inputs'!S83>=0),'Model inputs'!S83>=0,IF('Model inputs'!S83="","",'Model inputs'!S83>=0))),IF(IF(IF(ISERROR('Model inputs'!Z121=0),'Model inputs'!Z121=0,IF('Model inputs'!Z121="","",'Model inputs'!Z121=0))="",FALSE,IF(ISERROR('Model inputs'!Z121=0),'Model inputs'!Z121=0,IF('Model inputs'!Z121="","",'Model inputs'!Z121=0))),"Cash-positive; no launch buffer","Cash-positive within flat forecast"),"Cash-burning; see runway") -> Cash-positive; no launch buffer | L23: =IF(IF(IF(ISERROR('Model inputs'!T83>=0),'Model inputs'!T83>=0,IF('Model inputs'!T83="","",'Model inputs'!T83>=0))="",FALSE,IF(ISERROR('Model inputs'!T83>=0),'Model inputs'!T83>=0,IF('Model inputs'!T83="","",'Model inputs'!T83>=0))),IF(IF(IF(ISERROR('Model inputs'!Z121=0),'Model inputs'!Z121=0,IF('Model inputs'!Z121="","",'Model inputs'!Z121=0))="",FALSE,IF(ISERROR('Model inputs'!Z121=0),'Model inputs'!Z121=0,IF('Model inputs'!Z121="","",'Model inputs'!Z121=0))),"Cash-positive; no launch buffer","Cash-positive within flat forecast"),"Cash-burning; see runway") -> Cash-positive; no launch buffer | M23: =IF(IF(IF(ISERROR('Model inputs'!U83>=0),'Model inputs'!U83>=0,IF('Model inputs'!U83="","",'Model inputs'!U83>=0))="",FALSE,IF(ISERROR('Model inputs'!U83>=0),'Model inputs'!U83>=0,IF('Model inputs'!U83="","",'Model inputs'!U83>=0))),IF(IF(IF(ISERROR('Model inputs'!Z121=0),'Model inputs'!Z121=0,IF('Model inputs'!Z121="","",'Model inputs'!Z121=0))="",FALSE,IF(ISERROR('Model inputs'!Z121=0),'Model inputs'!Z121=0,IF('Model inputs'!Z121="","",'Model inputs'!Z121=0))),"Cash-positive; no launch buffer","Cash-positive within flat forecast"),"Cash-burning; see runway") -> Cash-positive; no launch buffer | N23: =IF(IF(IF(ISERROR('Model inputs'!V83>=0),'Model inputs'!V83>=0,IF('Model inputs'!V83="","",'Model inputs'!V83>=0))="",FALSE,IF(ISERROR('Model inputs'!V83>=0),'Model inputs'!V83>=0,IF('Model inputs'!V83="","",'Model inputs'!V83>=0))),IF(IF(IF(ISERROR('Model inputs'!Z121=0),'Model inputs'!Z121=0,IF('Model inputs'!Z121="","",'Model inputs'!Z121=0))="",FALSE,IF(ISERROR('Model inputs'!Z121=0),'Model inputs'!Z121=0,IF('Model inputs'!Z121="","",'Model inputs'!Z121=0))),"Cash-positive; no launch buffer","Cash-positive within flat forecast"),"Cash-burning; see runway") -> Cash-positive; no launch buffer | O23: =IF(IF(IF(ISERROR('Model inputs'!W83>=0),'Model inputs'!W83>=0,IF('Model inputs'!W83="","",'Model inputs'!W83>=0))="",FALSE,IF(ISERROR('Model inputs'!W83>=0),'Model inputs'!W83>=0,IF('Model inputs'!W83="","",'Model inputs'!W83>=0))),IF(IF(IF(ISERROR('Model inputs'!Z121=0),'Model inputs'!Z121=0,IF('Model inputs'!Z121="","",'Model inputs'!Z121=0))="",FALSE,IF(ISERROR('Model inputs'!Z121=0),'Model inputs'!Z121=0,IF('Model inputs'!Z121="","",'Model inputs'!Z121=0))),"Cash-positive; no launch buffer","Cash-positive within flat forecast"),"Cash-burning; see runway") -> Cash-positive; no launch buffer | P23: =IF(IF(IF(ISERROR('Model inputs'!X83>=0),'Model inputs'!X83>=0,IF('Model inputs'!X83="","",'Model inputs'!X83>=0))="",FALSE,IF(ISERROR('Model inputs'!X83>=0),'Model inputs'!X83>=0,IF('Model inputs'!X83="","",'Model inputs'!X83>=0))),IF(IF(IF(ISERROR('Model inputs'!Z121=0),'Model inputs'!Z121=0,IF('Model inputs'!Z121="","",'Model inputs'!Z121=0))="",FALSE,IF(ISERROR('Model inputs'!Z121=0),'Model inputs'!Z121=0,IF('Model inputs'!Z121="","",'Model inputs'!Z121=0))),"Cash-positive; no launch buffer","Cash-positive within flat forecast"),"Cash-burning; see runway") -> Cash-positive; no launch buffer | Q23: =IF(IF(IF(ISERROR('Model inputs'!Y83>=0),'Model inputs'!Y83>=0,IF('Model inputs'!Y83="","",'Model inputs'!Y83>=0))="",FALSE,IF(ISERROR('Model inputs'!Y83>=0),'Model inputs'!Y83>=0,IF('Model inputs'!Y83="","",'Model inputs'!Y83>=0))),IF(IF(IF(ISERROR('Model inputs'!Z121=0),'Model inputs'!Z121=0,IF('Model inputs'!Z121="","",'Model inputs'!Z121=0))="",FALSE,IF(ISERROR('Model inputs'!Z121=0),'Model inputs'!Z121=0,IF('Model inputs'!Z121="","",'Model inputs'!Z121=0))),"Cash-positive; no launch buffer","Cash-positive within flat forecast"),"Cash-burning; see runway") -> Cash-positive; no launch buffer
A24: Illustrative pre-seed — $25,000 | C24: =IF(IF(IF(ISERROR('Briefcase conversion and cost s'!B65>=0),'Briefcase conversion and cost s'!B65>=0,IF('Briefcase conversion and cost s'!B65="","",'Briefcase conversion and cost s'!B65>=0))="",FALSE,IF(ISERROR('Briefcase conversion and cost s'!B65>=0),'Briefcase conversion and cost s'!B65>=0,IF('Briefcase conversion and cost s'!B65="","",'Briefcase conversion and cost s'!B65>=0))),IF(IF(IF(ISERROR('Model inputs'!Z122=0),'Model inputs'!Z122=0,IF('Model inputs'!Z122="","",'Model inputs'!Z122=0))="",FALSE,IF(ISERROR('Model inputs'!Z122=0),'Model inputs'!Z122=0,IF('Model inputs'!Z122="","",'Model inputs'!Z122=0))),"Cash-positive; no launch buffer","Cash-positive within flat forecast"),"Cash-burning; see runway") -> Cash-positive within flat forecast | D24: =IF(IF(IF(ISERROR('Model inputs'!L83>=0),'Model inputs'!L83>=0,IF('Model inputs'!L83="","",'Model inputs'!L83>=0))="",FALSE,IF(ISERROR('Model inputs'!L83>=0),'Model inputs'!L83>=0,IF('Model inputs'!L83="","",'Model inputs'!L83>=0))),IF(IF(IF(ISERROR('Model inputs'!Z122=0),'Model inputs'!Z122=0,IF('Model inputs'!Z122="","",'Model inputs'!Z122=0))="",FALSE,IF(ISERROR('Model inputs'!Z122=0),'Model inputs'!Z122=0,IF('Model inputs'!Z122="","",'Model inputs'!Z122=0))),"Cash-positive; no launch buffer","Cash-positive within flat forecast"),"Cash-burning; see runway") -> Cash-positive within flat forecast | E24: =IF(IF(IF(ISERROR('Model inputs'!M83>=0),'Model inputs'!M83>=0,IF('Model inputs'!M83="","",'Model inputs'!M83>=0))="",FALSE,IF(ISERROR('Model inputs'!M83>=0),'Model inputs'!M83>=0,IF('Model inputs'!M83="","",'Model inputs'!M83>=0))),IF(IF(IF(ISERROR('Model inputs'!Z122=0),'Model inputs'!Z122=0,IF('Model inputs'!Z122="","",'Model inputs'!Z122=0))="",FALSE,IF(ISERROR('Model inputs'!Z122=0),'Model inputs'!Z122=0,IF('Model inputs'!Z122="","",'Model inputs'!Z122=0))),"Cash-positive; no launch buffer","Cash-positive within flat forecast"),"Cash-burning; see runway") -> Cash-positive within flat forecast | F24: =IF(IF(IF(ISERROR('Model inputs'!N83>=0),'Model inputs'!N83>=0,IF('Model inputs'!N83="","",'Model inputs'!N83>=0))="",FALSE,IF(ISERROR('Model inputs'!N83>=0),'Model inputs'!N83>=0,IF('Model inputs'!N83="","",'Model inputs'!N83>=0))),IF(IF(IF(ISERROR('Model inputs'!Z122=0),'Model inputs'!Z122=0,IF('Model inputs'!Z122="","",'Model inputs'!Z122=0))="",FALSE,IF(ISERROR('Model inputs'!Z122=0),'Model inputs'!Z122=0,IF('Model inputs'!Z122="","",'Model inputs'!Z122=0))),"Cash-positive; no launch buffer","Cash-positive within flat forecast"),"Cash-burning; see runway") -> Cash-positive within flat forecast | G24: =IF(IF(IF(ISERROR('Model inputs'!O83>=0),'Model inputs'!O83>=0,IF('Model inputs'!O83="","",'Model inputs'!O83>=0))="",FALSE,IF(ISERROR('Model inputs'!O83>=0),'Model inputs'!O83>=0,IF('Model inputs'!O83="","",'Model inputs'!O83>=0))),IF(IF(IF(ISERROR('Model inputs'!Z122=0),'Model inputs'!Z122=0,IF('Model inputs'!Z122="","",'Model inputs'!Z122=0))="",FALSE,IF(ISERROR('Model inputs'!Z122=0),'Model inputs'!Z122=0,IF('Model inputs'!Z122="","",'Model inputs'!Z122=0))),"Cash-positive; no launch buffer","Cash-positive within flat forecast"),"Cash-burning; see runway") -> Cash-positive within flat forecast | H24: =IF(IF(IF(ISERROR('Model inputs'!P83>=0),'Model inputs'!P83>=0,IF('Model inputs'!P83="","",'Model inputs'!P83>=0))="",FALSE,IF(ISERROR('Model inputs'!P83>=0),'Model inputs'!P83>=0,IF('Model inputs'!P83="","",'Model inputs'!P83>=0))),IF(IF(IF(ISERROR('Model inputs'!Z122=0),'Model inputs'!Z122=0,IF('Model inputs'!Z122="","",'Model inputs'!Z122=0))="",FALSE,IF(ISERROR('Model inputs'!Z122=0),'Model inputs'!Z122=0,IF('Model inputs'!Z122="","",'Model inputs'!Z122=0))),"Cash-positive; no launch buffer","Cash-positive within flat forecast"),"Cash-burning; see runway") -> Cash-positive within flat forecast | I24: =IF(IF(IF(ISERROR('Model inputs'!Q83>=0),'Model inputs'!Q83>=0,IF('Model inputs'!Q83="","",'Model inputs'!Q83>=0))="",FALSE,IF(ISERROR('Model inputs'!Q83>=0),'Model inputs'!Q83>=0,IF('Model inputs'!Q83="","",'Model inputs'!Q83>=0))),IF(IF(IF(ISERROR('Model inputs'!Z122=0),'Model inputs'!Z122=0,IF('Model inputs'!Z122="","",'Model inputs'!Z122=0))="",FALSE,IF(ISERROR('Model inputs'!Z122=0),'Model inputs'!Z122=0,IF('Model inputs'!Z122="","",'Model inputs'!Z122=0))),"Cash-positive; no launch buffer","Cash-positive within flat forecast"),"Cash-burning; see runway") -> Cash-positive within flat forecast | J24: =IF(IF(IF(ISERROR('Model inputs'!R83>=0),'Model inputs'!R83>=0,IF('Model inputs'!R83="","",'Model inputs'!R83>=0))="",FALSE,IF(ISERROR('Model inputs'!R83>=0),'Model inputs'!R83>=0,IF('Model inputs'!R83="","",'Model inputs'!R83>=0))),IF(IF(IF(ISERROR('Model inputs'!Z122=0),'Model inputs'!Z122=0,IF('Model inputs'!Z122="","",'Model inputs'!Z122=0))="",FALSE,IF(ISERROR('Model inputs'!Z122=0),'Model inputs'!Z122=0,IF('Model inputs'!Z122="","",'Model inputs'!Z122=0))),"Cash-positive; no launch buffer","Cash-positive within flat forecast"),"Cash-burning; see runway") -> Cash-positive within flat forecast | K24: =IF(IF(IF(ISERROR('Model inputs'!S83>=0),'Model inputs'!S83>=0,IF('Model inputs'!S83="","",'Model inputs'!S83>=0))="",FALSE,IF(ISERROR('Model inputs'!S83>=0),'Model inputs'!S83>=0,IF('Model inputs'!S83="","",'Model inputs'!S83>=0))),IF(IF(IF(ISERROR('Model inputs'!Z122=0),'Model inputs'!Z122=0,IF('Model inputs'!Z122="","",'Model inputs'!Z122=0))="",FALSE,IF(ISERROR('Model inputs'!Z122=0),'Model inputs'!Z122=0,IF('Model inputs'!Z122="","",'Model inputs'!Z122=0))),"Cash-positive; no launch buffer","Cash-positive within flat forecast"),"Cash-burning; see runway") -> Cash-positive within flat forecast | L24: =IF(IF(IF(ISERROR('Model inputs'!T83>=0),'Model inputs'!T83>=0,IF('Model inputs'!T83="","",'Model inputs'!T83>=0))="",FALSE,IF(ISERROR('Model inputs'!T83>=0),'Model inputs'!T83>=0,IF('Model inputs'!T83="","",'Model inputs'!T83>=0))),IF(IF(IF(ISERROR('Model inputs'!Z122=0),'Model inputs'!Z122=0,IF('Model inputs'!Z122="","",'Model inputs'!Z122=0))="",FALSE,IF(ISERROR('Model inputs'!Z122=0),'Model inputs'!Z122=0,IF('Model inputs'!Z122="","",'Model inputs'!Z122=0))),"Cash-positive; no launch buffer","Cash-positive within flat forecast"),"Cash-burning; see runway") -> Cash-positive within flat forecast | M24: =IF(IF(IF(ISERROR('Model inputs'!U83>=0),'Model inputs'!U83>=0,IF('Model inputs'!U83="","",'Model inputs'!U83>=0))="",FALSE,IF(ISERROR('Model inputs'!U83>=0),'Model inputs'!U83>=0,IF('Model inputs'!U83="","",'Model inputs'!U83>=0))),IF(IF(IF(ISERROR('Model inputs'!Z122=0),'Model inputs'!Z122=0,IF('Model inputs'!Z122="","",'Model inputs'!Z122=0))="",FALSE,IF(ISERROR('Model inputs'!Z122=0),'Model inputs'!Z122=0,IF('Model inputs'!Z122="","",'Model inputs'!Z122=0))),"Cash-positive; no launch buffer","Cash-positive within flat forecast"),"Cash-burning; see runway") -> Cash-positive within flat forecast | N24: =IF(IF(IF(ISERROR('Model inputs'!V83>=0),'Model inputs'!V83>=0,IF('Model inputs'!V83="","",'Model inputs'!V83>=0))="",FALSE,IF(ISERROR('Model inputs'!V83>=0),'Model inputs'!V83>=0,IF('Model inputs'!V83="","",'Model inputs'!V83>=0))),IF(IF(IF(ISERROR('Model inputs'!Z122=0),'Model inputs'!Z122=0,IF('Model inputs'!Z122="","",'Model inputs'!Z122=0))="",FALSE,IF(ISERROR('Model inputs'!Z122=0),'Model inputs'!Z122=0,IF('Model inputs'!Z122="","",'Model inputs'!Z122=0))),"Cash-positive; no launch buffer","Cash-positive within flat forecast"),"Cash-burning; see runway") -> Cash-positive within flat forecast | O24: =IF(IF(IF(ISERROR('Model inputs'!W83>=0),'Model inputs'!W83>=0,IF('Model inputs'!W83="","",'Model inputs'!W83>=0))="",FALSE,IF(ISERROR('Model inputs'!W83>=0),'Model inputs'!W83>=0,IF('Model inputs'!W83="","",'Model inputs'!W83>=0))),IF(IF(IF(ISERROR('Model inputs'!Z122=0),'Model inputs'!Z122=0,IF('Model inputs'!Z122="","",'Model inputs'!Z122=0))="",FALSE,IF(ISERROR('Model inputs'!Z122=0),'Model inputs'!Z122=0,IF('Model inputs'!Z122="","",'Model inputs'!Z122=0))),"Cash-positive; no launch buffer","Cash-positive within flat forecast"),"Cash-burning; see runway") -> Cash-positive within flat forecast | P24: =IF(IF(IF(ISERROR('Model inputs'!X83>=0),'Model inputs'!X83>=0,IF('Model inputs'!X83="","",'Model inputs'!X83>=0))="",FALSE,IF(ISERROR('Model inputs'!X83>=0),'Model inputs'!X83>=0,IF('Model inputs'!X83="","",'Model inputs'!X83>=0))),IF(IF(IF(ISERROR('Model inputs'!Z122=0),'Model inputs'!Z122=0,IF('Model inputs'!Z122="","",'Model inputs'!Z122=0))="",FALSE,IF(ISERROR('Model inputs'!Z122=0),'Model inputs'!Z122=0,IF('Model inputs'!Z122="","",'Model inputs'!Z122=0))),"Cash-positive; no launch buffer","Cash-positive within flat forecast"),"Cash-burning; see runway") -> Cash-positive within flat forecast | Q24: =IF(IF(IF(ISERROR('Model inputs'!Y83>=0),'Model inputs'!Y83>=0,IF('Model inputs'!Y83="","",'Model inputs'!Y83>=0))="",FALSE,IF(ISERROR('Model inputs'!Y83>=0),'Model inputs'!Y83>=0,IF('Model inputs'!Y83="","",'Model inputs'!Y83>=0))),IF(IF(IF(ISERROR('Model inputs'!Z122=0),'Model inputs'!Z122=0,IF('Model inputs'!Z122="","",'Model inputs'!Z122=0))="",FALSE,IF(ISERROR('Model inputs'!Z122=0),'Model inputs'!Z122=0,IF('Model inputs'!Z122="","",'Model inputs'!Z122=0))),"Cash-positive; no launch buffer","Cash-positive within flat forecast"),"Cash-burning; see runway") -> Cash-positive within flat forecast
